Workbook

Sheet 📋 INSTRUÇÕES
B1: K Controllers | Relatório de Volumetria e Produtividade
A2: Controladoria Jurídica na prática.
B5: COMO USAR ESTE MODELO
B7: ① ABA ➜ BASE DE DADOS
B8: Cole aqui os dados exportados do seu sistema de gestão.
B9: Cada linha = 1 processo ou 1 prazo.
B10: Não altere os cabeçalhos - as fórmulas dependem deles.
B12: ② ABA ➜ VOLUMETRIA DE PROCESSOS
B13: Atualiza automaticamente a partir da BASE DE DADOS.
B14: Mostra: total por área, por fase, por advogado e curva de ajuizamento.
B16: ③ ABA ➜ PRODUTIVIDADE E PRAZOS
B17: Atualiza automaticamente. Não edite as células com fórmulas.
B18: Mostra: prazos por tipo, taxa de cumprimento, performance por advogado.
B20: DICAS IMPORTANTES
... B34: kcontrollers.com.br | Uso exclusivo K Controllers

Sheet BASE DE DADOS
A1: SEÇÃO 1 — PROCESSOS | I1: SEÇÃO 2 — PRAZOS
A2: Preencha uma linha por processo ativo. Não deixe linhas em branco no meio. | I2: Preencha um prazo por linha. Status: Cumprido | Pendente | Não cumprido
A3: Nº Processo | B3: Área / Matéria | C3: Fase Processual | D3: Responsável (Advogado) | E3: Data Ajuizamento | F3: Vara / Tribunal | G3: Observação | I3: Nº Processo | J3: Tipo de Prazo | K3: Data Limite | L3: Responsável (Advogado) | M3: Status do Prazo | N3: Data Cumprimento | O3: Observação
A4: 5005212-03.2026.8.24.0020 | B4: Outras | D4: Renata Francisco Becker | E4: 46002 | I4: 01560009520055120033 | J4: Tarefa | K4: 46027 | L4: Pedro Victor | M4: Cumprido | N4: 46027 | O4: Pedido de redução de desconto
A5: 5008937-34.2025.8.24.0020 | B5: Outras | D5: Renata Francisco Becker | E5: 45769 | F5: 2° vara cível | J5: Tarefa | K5: 46027 | L5: Julia | M5: Cumprido | N5: 46027 | O5: Registro de Marca Reficel e Valen
B6: Outras | D6: Marelize Controladoria | E6: 46073 | J6: Evento | K6: 46027 | L6: Marelize Controladoria | M6: Cumprido | N6: 46027 | O6: Reunião controladoria (Nathalia)
A7: 5001371-18.2024.8.24.0166 | B7: Outras | D7: Renata Francisco Becker | E7: 45448 | J7: Tarefa | K7: 46028 | L7: Marelize Controladoria | M7: Cumprido | N7: 46028 | O7: Lize, consegue aplicar o cronograma do Lucas, na agenda dele, conforme conversamos. Se conseguir fazer antes do retorno dele, agradeço,
A8: 0301909-52.2015.8.24.0028 | B8: Outras | D8: Marelize Controladoria | E8: 46105 | F8: Juízo da 1ª Vara Cível da Comarca de Içara | I8: 40013348420268260100 | J8: Tarefa | K8: 46029 | L8: Renata Francisco Becker | M8: Cumprido | N8: 46029 | O8: CONFERÊNCIA IMPORTANTE MI - Cobrança Monto - MMC
A9: 5000212-03.2018.8.24.0020 | B9: Outras | D9: Renata Francisco Becker | E9: 44761 | F9: Juízo da 2ª Vara Cível da Comarca de Criciúma | J9: Tarefa | K9: 46029 | L9: Marelize Controladoria | M9: Cumprido | N9: 46029 | O9: Por favor, consegue verificar como funciona essa questão no Astrea de atividades pré definidas. Para podermos implementar… Segundo o Astrea, ótima o tempo da distribuição das publicacoes
B10: Outras | D10: Marelize Controladoria | E10: 46100 | J10: Tarefa | K10: 46029 | L10: Marelize Controladoria | M10: Cumprido | N10: 46029 | O10: DISTRIBUIR TAREFAS (Pedro grupo controladoria)
A11: 5133128-39.2026.8.09.0084 | B11: Outras | D11: Marelize Controladoria | E11: 46071 | I11: 5020941-06.2025.8.24.0020 | J11: Tarefa | K11: 46029 | L11: Marelize Controladoria | M11: Cumprido | N11: 46029 | O11: Redesignado audiencia, avisar cliente, anotar nas agendas
A12: 50055518420238240078 | B12: Outras | D12: Renata Francisco Becker | E12: 45338 | J12: Evento | K12: 46029 | L12: Renata Francisco Becker | M12: Cumprido | N12: 46029 | O12: Reunião Nika - pavilhao
B13: Outras | D13: Pedro Victor | E13: 46059 | J13: Evento | K13: 46029 | L13: Renata Francisco Becker | M13: Cumprido | N13: 46029 | O13: Atendimento Renata
A14: 0028206-72.2010.8.24.0020 | B14: Outras | D14: Renata Francisco Becker | E14: 45685 | F14: Vara da Família | J14: Prazo | K14: 46030 | L14: Alexia | M14: Cumprido | N14: 46030 | O14: Prazo 19.12-defesa-prorrogação
B15: Outras | D15: Marelize Controladoria | E15: 46080 | J15: Tarefa | K15: 46030 | L15: Julia | M15: Cumprido | N15: 46030 | O15: FAZER AÇÃO RECISÓRIA CONTRATUAL
A16: 0001022-55.2025.5.12.0003 | B16: Outras | D16: Renata Francisco Becker | E16: 45890 | F16: Vara do Trabalho | J16: Tarefa | K16: 46030 | L16: Marelize Controladoria | M16: Cumprido | N16: 46030 | O16: Verificar demanda Perdoná
A17: 5012554-02.2025.8.24.0020 | B17: Outras | D17: Renata Francisco Becker | E17: 45813 | J17: Tarefa | K17: 46030 | L17: Jessica | M17: Cumprido | N17: 46030 | O17: PLANEJAMENTO TRIBUTÁRIO DA PAPA JOHN
B18: Outras | D18: Marelize Controladoria | E18: 46072 | J18: Tarefa | K18: 46030 | L18: Julia | M18: Cumprido | N18: 46030 | O18: Análise de Contratos Adicionais Ação: Analisar e revisar dois modelos de contrato de grande porte utilizados pela Granda Engenharia.
A19: 5000200-62.2025.8.24.0175 | B19: Outras | D19: Renata Francisco Becker | E19: 45786 | F19: Vara Única | I19: 50000591320248240940 | J19: Tarefa | K19: 46030 | L19: Jessica | M19: Cumprido | N19: 46030 | O19: Conferir CDA juntada no PAF com a do processo para ver se é exatamente a mesma
A20: 5003424-51.2026.8.24.0020 | B20: Outras | D20: Marelize Controladoria | E20: 46099 | F20: Juízo da 4ª Vara Cível da Comarca de Criciúma | J20: Tarefa | K20: 46030 | L20: Lucas | M20: Cumprido | N20: 46030 | O20: Fazer regimento interno.
A21: 0000459-98.2025.5.12.0023 | B21: Outras | D21: Luci | E21: 45779 | J21: Tarefa | K21: 46030 | L21: Julia | M21: Cumprido | N21: 46030 | O21: Joel pediu para analisar a declaração de ciencia e autorização para protocolo e ver o que posso aprimorar - pediu para Julia na reuniao do dia 17/12/2025
A22: 0028824-87.2025.8.19.0001 | B22: Outras | D22: Renata Francisco Becker | E22: 45727 | F22: 2° Vara Especializada | J22: Evento | K22: 46030 | L22: Marelize Controladoria | M22: Cumprido | N22: 46030 | O22: Reunião inicial com a Karia - IMPLEMENTAÇÃO
A23: 1025830-78.2026.8.26.0053 | B23: Outras | D23: Marelize Controladoria | E23: 46087 | F23: 7ª Vara de Fazenda Pública | J23: Evento | K23: 46030 | L23: Renata Francisco Becker | M23: Cumprido | N23: 46030 | O23: Atendimento inventario Jessica
A24: 5024640-10.2022.8.24.0020 | B24: Outras | D24: Renata Francisco Becker | E24: 44858 | J24: Prazo | K24: 46031 | L24: Julia | M24: Cumprido | N24: 46031 | O24: Atualizar contrato de tercerização
A25: 0005476-39.2025.8.26.0100 | B25: Outras | D25: Marelize Controladoria | E25: 46059 | F25: 1ª Vara de Falências e Recuperações Judiciais | J25: Prazo | K25: 46031 | L25: Lucas | M25: Cumprido | N25: 46031 | O25: Demanda Expresso Veneza (Lucas)
A26: 5005551-84.2023.8.24.0078 | B26: Outras | D26: Pedro Victor | E26: 45337 | F26: Vara Cível | J26: Prazo | K26: 46031 | L26: Lucas | M26: Cumprido | N26: 46031 | O26: Demanda Vonscher (DET)
A27: 5011984-50.2024.8.24.0020 | B27: Outras | D27: Renata Francisco Becker | E27: 45426 | F27: Vara Cível | I27: 09.2022.00002328-6 | J27: Prazo | K27: 46031 | L27: Lucas | M27: Cumprido | N27: 46031 | O27: Prazo
A28: 0001682-49.2025.5.12.0003 | B28: Outras | D28: Marelize Controladoria | E28: 46035 | F28: 1ª VARA DO TRABALHO DE CRICIÚMA | I28: 5006390-88.2025.8.24.0030 | J28: Prazo | K28: 46031 | L28: Renata Francisco Becker | M28: Cumprido | N28: 46031 | O28: Prazo Crime
A29: 5004196-94.2020.4.04.7204 | B29: Outras | D29: Renata Francisco Becker | E29: 44789 | F29: Juízo Federal da 4ª VF de Criciúma | J29: Prazo | K29: 46031 | L29: Jessica | M29: Cumprido | N29: 46031 | O29: prazo pedido caducidade
A30: 5012167-67.2019.4.04.7204 | B30: Outras | D30: Renata Francisco Becker | E30: 44725 | F30: Juízo Substituto da 4ª VF de Criciúma | I30: 5005478-34.2024.8.24.0028 | J30: Prazo | K30: 46031 | L30: Renata Francisco Becker | M30: Cumprido | N30: 46031 | O30: RENUNCIA RECAPADORA
A31: 5000429-88.2021.8.24.0166 | B31: Outras | D31: Renata Francisco Becker | E31: 44701 | F31: Juizo Da Vara Unica Da Comarca De Forquilhinha | J31: Tarefa | K31: 46031 | L31: Lucas | M31: Cumprido | N31: 46031 | O31: 09/01/2026 - CONFERIR ATIVIDADES MONITORADAS
A32: 5004194-27.2020.4.04.7204 | B32: Outras | D32: Renata Francisco Becker | E32: 44798 | F32: 4 | J32: Tarefa | K32: 46031 | L32: Renata Francisco Becker | M32: Cumprido | N32: 46031 | O32: Elaboração
A33: 5012238-69.2019.4.04.7204 | B33: Outras | D33: Renata Francisco Becker | E33: 44719 | F33: Juízo Federal da 4ª VF de Criciúma | I33: 09.2022.00002328-6 | J33: Tarefa | K33: 46031 | L33: Lucas | M33: Cumprido | N33: 46031 | O33: Elaboração
A34: 5020732-76.2021.8.24.0020 | B34: Outras | D34: Renata Francisco Becker | E34: 44781 | F34: Juízo da Vara da Infância e Juventude e Anexos da Comarca de Criciúma | J34: Tarefa | K34: 46031 | L34: Julia | M34: Cumprido | N34: 46031 | O34: Elaboração
A35: 1000101-23.2021.8.26.0539 | B35: Outras | D35: Renata Francisco Becker | E35: 45764 | F35: 3ª Vara Cível | J35: Tarefa | K35: 46031 | L35: Renata Francisco Becker | M35: Cumprido | N35: 46031 | O35: Finalizar agenda Lucas (jud e adm)
A36: 5032306-91.2024.8.24.0020 | B36: Outras | D36: Pedro Victor | E36: 45593 | I36: 09.2022.00002328-6 | J36: Tarefa | K36: 46031 | L36: Lucas | M36: Cumprido | N36: 46031 | O36: Protocolo
A37: 5017084-75.2026.8.24.0000 | B37: Outras | D37: Pedro Victor | E37: 46084 | J37: Tarefa | K37: 46031 | L37: Julia | M37: Cumprido | N37: 46031 | O37: REVISAR URGENTE - Notificação de devolução de valores - Mega Máquinas
B38: Outras | D38: Marelize Controladoria | E38: 46052 | I38: 09.2022.00002328-6 | J38: Tarefa | K38: 46031 | L38: Renata Francisco Becker | M38: Cumprido | N38: 46031 | O38: Revisão
A39: 03063527020158240020 | B39: Outras | D39: Pedro Victor | E39: 45877 | F39: Juízo da 1ª Vara da Fazenda Pública da Comarca de Criciúma | I39: 09.2022.00002328-6 | J39: Tarefa | K39: 46031 | L39: Lucas | M39: Cumprido | N39: 46031 | O39: Revisão
B40: Outras | D40: Marelize Controladoria | E40: 46083 | J40: Tarefa | K40: 46031 | L40: Julia | M40: Cumprido | N40: 46031 | O40: Revisão
...

Sheet VOLUMETRIA DE PROCESSOS
A1: VOLUMETRIA DE PROCESSOS
A2: Atualização automática a partir da BASE DE DADOS | Não edite esta aba
B4: PROCESSOS POR ÁREA / MATÉRIA | G4: PROCESSOS POR FASE PROCESSUAL
B5: Área / Matéria | C5: Qtd. Processos | D5: % do Total | G5: Fase Processual | H5: Qtd. Processos | I5: % do Total
B6: Cível | C6: =COUNTIF('BASE DE DADOS'!$B$4:$B$3000,B6) | D6: =IF(C6=0,"-",TEXT(C6/C14,"0.0%")) | G6: Conhecimento | H6: =COUNTIF('BASE DE DADOS'!$C$4:$C$3000,G6) | I6: =IF(H6=0,"-",TEXT(H6/H13,"0.0%"))
B7: Trabalhista | C7: =COUNTIF('BASE DE DADOS'!$B$4:$B$3000,B7) | D7: =IF(C7=0,"-",TEXT(C7/C14,"0.0%")) | G7: Recurso | H7: =COUNTIF('BASE DE DADOS'!$C$4:$C$3000,G7) | I7: =IF(H7=0,"-",TEXT(H7/H13,"0.0%"))
B8: Tributário | C8: =COUNTIF('BASE DE DADOS'!$B$4:$B$3000,B8) | D8: =IF(C8=0,"-",TEXT(C8/C14,"0.0%")) | G8: Execução | H8: =COUNTIF('BASE DE DADOS'!$C$4:$C$3000,G8) | I8: =IF(H8=0,"-",TEXT(H8/H13,"0.0%"))
B9: Previdenciário | C9: =COUNTIF('BASE DE DADOS'!$B$4:$B$3000,B9) | D9: =IF(C9=0,"-",TEXT(C9/C14,"0.0%")) | G9: Cumprimento de Sentença | H9: =COUNTIF('BASE DE DADOS'!$C$4:$C$3000,G9) | I9: =IF(H9=0,"-",TEXT(H9/H13,"0.0%"))
B10: Criminal | C10: =COUNTIF('BASE DE DADOS'!$B$4:$B$3000,B10) | D10: =IF(C10=0,"-",TEXT(C10/C14,"0.0%")) | G10: Transitado em Julgado | H10: =COUNTIF('BASE DE DADOS'!$C$4:$C$3000,G10) | I10: =IF(H10=0,"-",TEXT(H10/H13,"0.0%"))
B11: Família | C11: =COUNTIF('BASE DE DADOS'!$B$4:$B$3000,B11) | D11: =IF(C11=0,"-",TEXT(C11/C14,"0.0%")) | G11: Suspenso | H11: =COUNTIF('BASE DE DADOS'!$C$4:$C$3000,G11) | I11: =IF(H11=0,"-",TEXT(H11/H13,"0.0%"))
B12: Empresarial | C12: =COUNTIF('BASE DE DADOS'!$B$4:$B$3000,B12) | D12: =IF(C12=0,"-",TEXT(C12/C14,"0.0%")) | G12: Arquivado | H12: =COUNTIF('BASE DE DADOS'!$C$4:$C$3000,G12) | I12: =IF(H12=0,"-",TEXT(H12/H13,"0.0%"))
B13: Outras | C13: =COUNTIF('BASE DE DADOS'!$B$4:$B$3000,B13) | D13: =IF(C13=0,"-",TEXT(C13/C14,"0.0%")) | G13: TOTAL | H13: =SUM(H6:H12)
B14: TOTAL | C14: =SUM(C6:C13)
B16: PROCESSOS POR RESPONSÁVEL (ADVOGADO)
B17: Responsável | C17: Qtd. Processos | D17: % do Total
B18: Jessica | C18: =IF(B18="","",COUNTIF('BASE DE DADOS'!$D$4:$D$3000,B18)) | D18: =IF(OR(B18="",C18=0),"-",TEXT(C18/C14,"0.0%"))
B19: Julia | C19: =IF(B19="","",COUNTIF('BASE DE DADOS'!$D$4:$D$3000,B19)) | D19: =IF(OR(B19="",C19=0),"-",TEXT(C19/C14,"0.0%"))
B20: Lucas | C20: =IF(B20="","",COUNTIF('BASE DE DADOS'!$D$4:$D$3000,B20)) | D20: =IF(OR(B20="",C20=0),"-",TEXT(C20/C14,"0.0%"))
B21: Luci | C21: =IF(B21="","",COUNTIF('BASE DE DADOS'!$D$4:$D$3000,B21)) | D21: =IF(OR(B21="",C21=0),"-",TEXT(C21/C14,"0.0%"))
B22: Marelize Controladoria | C22: =IF(B22="","",COUNTIF('BASE DE DADOS'!$D$4:$D$3000,B22)) | D22: =IF(OR(B22="",C22=0),"-",TEXT(C22/C14,"0.0%"))
B23: Pedro Victor | C23: =IF(B23="","",COUNTIF('BASE DE DADOS'!$D$4:$D$3000,B23)) | D23: =IF(OR(B23="",C23=0),"-",TEXT(C23/C14,"0.0%"))
B24: Renata Francisco Becker | C24: =IF(B24="","",COUNTIF('BASE DE DADOS'!$D$4:$D$3000,B24)) | D24: =IF(OR(B24="",C24=0),"-",TEXT(C24/C14,"0.0%"))
B27: CURVA DE AJUIZAMENTO — PROCESSOS POR MÊS/ANO
B28: Mês/Ano | C28: Jan | D28: Fev | E28: Mar | F28: Abr | G28: Mai | H28: Jun | I28: Jul | J28: Ago | K28: Set | L28: Out | M28: Nov | N28: Dez | O28: Total Ano
B29: 2022 | C29: =COUNTIFS('BASE DE DADOS'!$E$4:$E$3000,">="&DATE($B29,MONTH(1&C$28),1),'BASE DE DADOS'!$E$4:$E$3000,"<="&EOMONTH(DATE($B29,MONTH(1&C$28),1),0)) | D29: =COUNTIFS('BASE DE DADOS'!$E$4:$E$3000,">="&DATE($B29,MONTH(1&D$28),1),'BASE DE DADOS'!$E$4:$E$3000,"<="&EOMONTH(DATE($B29,MONTH(1&D$28),1),0)) | E29: =COUNTIFS('BASE DE DADOS'!$E$4:$E$3000,">="&DATE($B29,MONTH(1&E$28),1),'BASE DE DADOS'!$E$4:$E$3000,"<="&EOMONTH(DATE($B29,MONTH(1&E$28),1),0)) | F29: =COUNTIFS('BASE DE DADOS'!$E$4:$E$3000,">="&DATE($B29,MONTH(1&F$28),1),'BASE DE DADOS'!$E$4:$E$3000,"<="&EOMONTH(DATE($B29,MONTH(1&F$28),1),0)) | G29: =COUNTIFS('BASE DE DADOS'!$E$4:$E$3000,">="&DATE($B29,MONTH(1&G$28),1),'BASE DE DADOS'!$E$4:$E$3000,"<="&EOMONTH(DATE($B29,MONTH(1&G$28),1),0)) | H29: =COUNTIFS('BASE DE DADOS'!$E$4:$E$3000,">="&DATE($B29,MONTH(1&H$28),1),'BASE DE DADOS'!$E$4:$E$3000,"<="&EOMONTH(DATE($B29,MONTH(1&H$28),1),0)) | I29: =COUNTIFS('BASE DE DADOS'!$E$4:$E$3000,">="&DATE($B29,MONTH(1&I$28),1),'BASE DE DADOS'!$E$4:$E$3000,"<="&EOMONTH(DATE($B29,MONTH(1&I$28),1),0)) | J29: =COUNTIFS('BASE DE DADOS'!$E$4:$E$3000,">="&DATE($B29,MONTH(1&J$28),1),'BASE DE DADOS'!$E$4:$E$3000,"<="&EOMONTH(DATE($B29,MONTH(1&J$28),1),0)) | ... N29: =COUNTIFS('BASE DE DADOS'!$E$4:$E$3000,">="&DATE($B29,MONTH(1&N$28),1),'BASE DE DADOS'!$E$4:$E$3000,"<="&EOMONTH(DATE($B29,MONTH(1&N$28),1),0)) | O29: =SUM(C29:N29)
B30: 2023 | C30: =COUNTIFS('BASE DE DADOS'!$E$4:$E$3000,">="&DATE($B30,MONTH(1&C$28),1),'BASE DE DADOS'!$E$4:$E$3000,"<="&EOMONTH(DATE($B30,MONTH(1&C$28),1),0)) | D30: =COUNTIFS('BASE DE DADOS'!$E$4:$E$3000,">="&DATE($B30,MONTH(1&D$28),1),'BASE DE DADOS'!$E$4:$E$3000,"<="&EOMONTH(DATE($B30,MONTH(1&D$28),1),0)) | E30: =COUNTIFS('BASE DE DADOS'!$E$4:$E$3000,">="&DATE($B30,MONTH(1&E$28),1),'BASE DE DADOS'!$E$4:$E$3000,"<="&EOMONTH(DATE($B30,MONTH(1&E$28),1),0)) | F30: =COUNTIFS('BASE DE DADOS'!$E$4:$E$3000,">="&DATE($B30,MONTH(1&F$28),1),'BASE DE DADOS'!$E$4:$E$3000,"<="&EOMONTH(DATE($B30,MONTH(1&F$28),1),0)) | G30: =COUNTIFS('BASE DE DADOS'!$E$4:$E$3000,">="&DATE($B30,MONTH(1&G$28),1),'BASE DE DADOS'!$E$4:$E$3000,"<="&EOMONTH(DATE($B30,MONTH(1&G$28),1),0)) | H30: =COUNTIFS('BASE DE DADOS'!$E$4:$E$3000,">="&DATE($B30,MONTH(1&H$28),1),'BASE DE DADOS'!$E$4:$E$3000,"<="&EOMONTH(DATE($B30,MONTH(1&H$28),1),0)) | I30: =COUNTIFS('BASE DE DADOS'!$E$4:$E$3000,">="&DATE($B30,MONTH(1&I$28),1),'BASE DE DADOS'!$E$4:$E$3000,"<="&EOMONTH(DATE($B30,MONTH(1&I$28),1),0)) | J30: =COUNTIFS('BASE DE DADOS'!$E$4:$E$3000,">="&DATE($B30,MONTH(1&J$28),1),'BASE DE DADOS'!$E$4:$E$3000,"<="&EOMONTH(DATE($B30,MONTH(1&J$28),1),0)) | ... N30: =COUNTIFS('BASE DE DADOS'!$E$4:$E$3000,">="&DATE($B30,MONTH(1&N$28),1),'BASE DE DADOS'!$E$4:$E$3000,"<="&EOMONTH(DATE($B30,MONTH(1&N$28),1),0)) | O30: =SUM(C30:N30)
B31: 2024 | C31: =COUNTIFS('BASE DE DADOS'!$E$4:$E$3000,">="&DATE($B31,MONTH(1&C$28),1),'BASE DE DADOS'!$E$4:$E$3000,"<="&EOMONTH(DATE($B31,MONTH(1&C$28),1),0)) | D31: =COUNTIFS('BASE DE DADOS'!$E$4:$E$3000,">="&DATE($B31,MONTH(1&D$28),1),'BASE DE DADOS'!$E$4:$E$3000,"<="&EOMONTH(DATE($B31,MONTH(1&D$28),1),0)) | E31: =COUNTIFS('BASE DE DADOS'!$E$4:$E$3000,">="&DATE($B31,MONTH(1&E$28),1),'BASE DE DADOS'!$E$4:$E$3000,"<="&EOMONTH(DATE($B31,MONTH(1&E$28),1),0)) | F31: =COUNTIFS('BASE DE DADOS'!$E$4:$E$3000,">="&DATE($B31,MONTH(1&F$28),1),'BASE DE DADOS'!$E$4:$E$3000,"<="&EOMONTH(DATE($B31,MONTH(1&F$28),1),0)) | G31: =COUNTIFS('BASE DE DADOS'!$E$4:$E$3000,">="&DATE($B31,MONTH(1&G$28),1),'BASE DE DADOS'!$E$4:$E$3000,"<="&EOMONTH(DATE($B31,MONTH(1&G$28),1),0)) | H31: =COUNTIFS('BASE DE DADOS'!$E$4:$E$3000,">="&DATE($B31,MONTH(1&H$28),1),'BASE DE DADOS'!$E$4:$E$3000,"<="&EOMONTH(DATE($B31,MONTH(1&H$28),1),0)) | I31: =COUNTIFS('BASE DE DADOS'!$E$4:$E$3000,">="&DATE($B31,MONTH(1&I$28),1),'BASE DE DADOS'!$E$4:$E$3000,"<="&EOMONTH(DATE($B31,MONTH(1&I$28),1),0)) | J31: =COUNTIFS('BASE DE DADOS'!$E$4:$E$3000,">="&DATE($B31,MONTH(1&J$28),1),'BASE DE DADOS'!$E$4:$E$3000,"<="&EOMONTH(DATE($B31,MONTH(1&J$28),1),0)) | ... N31: =COUNTIFS('BASE DE DADOS'!$E$4:$E$3000,">="&DATE($B31,MONTH(1&N$28),1),'BASE DE DADOS'!$E$4:$E$3000,"<="&EOMONTH(DATE($B31,MONTH(1&N$28),1),0)) | O31: =SUM(C31:N31)
B32: 2025 | C32: =COUNTIFS('BASE DE DADOS'!$E$4:$E$3000,">="&DATE($B32,MONTH(1&C$28),1),'BASE DE DADOS'!$E$4:$E$3000,"<="&EOMONTH(DATE($B32,MONTH(1&C$28),1),0)) | D32: =COUNTIFS('BASE DE DADOS'!$E$4:$E$3000,">="&DATE($B32,MONTH(1&D$28),1),'BASE DE DADOS'!$E$4:$E$3000,"<="&EOMONTH(DATE($B32,MONTH(1&D$28),1),0)) | E32: =COUNTIFS('BASE DE DADOS'!$E$4:$E$3000,">="&DATE($B32,MONTH(1&E$28),1),'BASE DE DADOS'!$E$4:$E$3000,"<="&EOMONTH(DATE($B32,MONTH(1&E$28),1),0)) | F32: =COUNTIFS('BASE DE DADOS'!$E$4:$E$3000,">="&DATE($B32,MONTH(1&F$28),1),'BASE DE DADOS'!$E$4:$E$3000,"<="&EOMONTH(DATE($B32,MONTH(1&F$28),1),0)) | G32: =COUNTIFS('BASE DE DADOS'!$E$4:$E$3000,">="&DATE($B32,MONTH(1&G$28),1),'BASE DE DADOS'!$E$4:$E$3000,"<="&EOMONTH(DATE($B32,MONTH(1&G$28),1),0)) | H32: =COUNTIFS('BASE DE DADOS'!$E$4:$E$3000,">="&DATE($B32,MONTH(1&H$28),1),'BASE DE DADOS'!$E$4:$E$3000,"<="&EOMONTH(DATE($B32,MONTH(1&H$28),1),0)) | I32: =COUNTIFS('BASE DE DADOS'!$E$4:$E$3000,">="&DATE($B32,MONTH(1&I$28),1),'BASE DE DADOS'!$E$4:$E$3000,"<="&EOMONTH(DATE($B32,MONTH(1&I$28),1),0)) | J32: =COUNTIFS('BASE DE DADOS'!$E$4:$E$3000,">="&DATE($B32,MONTH(1&J$28),1),'BASE DE DADOS'!$E$4:$E$3000,"<="&EOMONTH(DATE($B32,MONTH(1&J$28),1),0)) | ... N32: =COUNTIFS('BASE DE DADOS'!$E$4:$E$3000,">="&DATE($B32,MONTH(1&N$28),1),'BASE DE DADOS'!$E$4:$E$3000,"<="&EOMONTH(DATE($B32,MONTH(1&N$28),1),0)) | O32: =SUM(C32:N32)
B33: 2026 | C33: =COUNTIFS('BASE DE DADOS'!$E$4:$E$3000,">="&DATE($B33,MONTH(1&C$28),1),'BASE DE DADOS'!$E$4:$E$3000,"<="&EOMONTH(DATE($B33,MONTH(1&C$28),1),0)) | D33: =COUNTIFS('BASE DE DADOS'!$E$4:$E$3000,">="&DATE($B33,MONTH(1&D$28),1),'BASE DE DADOS'!$E$4:$E$3000,"<="&EOMONTH(DATE($B33,MONTH(1&D$28),1),0)) | E33: =COUNTIFS('BASE DE DADOS'!$E$4:$E$3000,">="&DATE($B33,MONTH(1&E$28),1),'BASE DE DADOS'!$E$4:$E$3000,"<="&EOMONTH(DATE($B33,MONTH(1&E$28),1),0)) | F33: =COUNTIFS('BASE DE DADOS'!$E$4:$E$3000,">="&DATE($B33,MONTH(1&F$28),1),'BASE DE DADOS'!$E$4:$E$3000,"<="&EOMONTH(DATE($B33,MONTH(1&F$28),1),0)) | G33: =COUNTIFS('BASE DE DADOS'!$E$4:$E$3000,">="&DATE($B33,MONTH(1&G$28),1),'BASE DE DADOS'!$E$4:$E$3000,"<="&EOMONTH(DATE($B33,MONTH(1&G$28),1),0)) | H33: =COUNTIFS('BASE DE DADOS'!$E$4:$E$3000,">="&DATE($B33,MONTH(1&H$28),1),'BASE DE DADOS'!$E$4:$E$3000,"<="&EOMONTH(DATE($B33,MONTH(1&H$28),1),0)) | I33: =COUNTIFS('BASE DE DADOS'!$E$4:$E$3000,">="&DATE($B33,MONTH(1&I$28),1),'BASE DE DADOS'!$E$4:$E$3000,"<="&EOMONTH(DATE($B33,MONTH(1&I$28),1),0)) | J33: =COUNTIFS('BASE DE DADOS'!$E$4:$E$3000,">="&DATE($B33,MONTH(1&J$28),1),'BASE DE DADOS'!$E$4:$E$3000,"<="&EOMONTH(DATE($B33,MONTH(1&J$28),1),0)) | ... N33: =COUNTIFS('BASE DE DADOS'!$E$4:$E$3000,">="&DATE($B33,MONTH(1&N$28),1),'BASE DE DADOS'!$E$4:$E$3000,"<="&EOMONTH(DATE($B33,MONTH(1&N$28),1),0)) | O33: =SUM(C33:N33)
B34: TOTAL | C34: =SUM(C29:C33) | D34: =SUM(D29:D33) | E34: =SUM(E29:E33) | F34: =SUM(F29:F33) | G34: =SUM(G29:G33) | H34: =SUM(H29:H33) | I34: =SUM(I29:I33) | J34: =SUM(J29:J33) | ... N34: =SUM(N29:N33)
B63: K Controllers | kcontrollers.com.br | Controladoria Jurídica na prática.

Sheet PRODUTIVIDADE E PRAZOS
A1: PRODUTIVIDADE E GESTÃO DE PRAZOS
A2: Produtividade com dados de 01.01.2026 a 28.02.2026
A3: Atualização automática a partir da BASE DE DADOS | Não edite esta aba
B5: PAINEL GERAL DE PRAZOS
B6: Indicador | C6: Qtd. | D6: % do Total
B7: Total de Prazos Cadastrados | C7: =COUNTA('BASE DE DADOS'!$M$4:$M$3000) | D7: =IF(C7=0,"-","100%")
B8: ✔ Prazos Cumpridos | C8: =COUNTIF('BASE DE DADOS'!$M$4:$M$3000,"Cumprido") | D8: =IF(C7=0,"-",TEXT(C8/C7,"0.0%"))
B9: ⏳ Prazos Pendentes | C9: =COUNTIF('BASE DE DADOS'!$M$4:$M$3000,"Pendente") | D9: =IF(C7=0,"-",TEXT(C9/C7,"0.0%"))
B10: ✘ Prazos Não Cumpridos | C10: =COUNTIF('BASE DE DADOS'!$M$4:$M$3000,"Não cumprido") | D10: =IF(C7=0,"-",TEXT(C10/C7,"0.0%"))
B11: TAXA DE CUMPRIMENTO DE PRAZOS | D11: =IF(C7=0,"-",TEXT(C8/(C8+C10),"0.0%")) | E11: ← Cumpridos ÷ (Cumpridos + Não cumpridos)
B13: PRAZOS POR TIPO
B14: Tipo de Prazo | C14: Total | D14: Cumpridos | E14: Não Cumpridos | F14: Taxa (%)
B15: Contestação | C15: =COUNTIF('BASE DE DADOS'!$J$4:$J$3000,B15) | D15: {=SUMPRODUCT(('BASE DE DADOS'!$J$4:$J$3000=B15)*('BASE DE DADOS'!$M$4:$M$3000="Cumprido"))} | E15: {=SUMPRODUCT(('BASE DE DADOS'!$J$4:$J$3000=B15)*('BASE DE DADOS'!$M$4:$M$3000="Não cumprido"))} | F15: =IF(C15=0,"-",TEXT(D15/C15,"0.0%"))
B16: Recurso de Apelação | C16: =COUNTIF('BASE DE DADOS'!$J$4:$J$3000,B16) | D16: {=SUMPRODUCT(('BASE DE DADOS'!$J$4:$J$3000=B16)*('BASE DE DADOS'!$M$4:$M$3000="Cumprido"))} | E16: {=SUMPRODUCT(('BASE DE DADOS'!$J$4:$J$3000=B16)*('BASE DE DADOS'!$M$4:$M$3000="Não cumprido"))} | F16: =IF(C16=0,"-",TEXT(D16/C16,"0.0%"))
B17: Agravo | C17: =COUNTIF('BASE DE DADOS'!$J$4:$J$3000,B17) | D17: {=SUMPRODUCT(('BASE DE DADOS'!$J$4:$J$3000=B17)*('BASE DE DADOS'!$M$4:$M$3000="Cumprido"))} | E17: {=SUMPRODUCT(('BASE DE DADOS'!$J$4:$J$3000=B17)*('BASE DE DADOS'!$M$4:$M$3000="Não cumprido"))} | F17: =IF(C17=0,"-",TEXT(D17/C17,"0.0%"))
B18: Manifestação | C18: =COUNTIF('BASE DE DADOS'!$J$4:$J$3000,B18) | D18: {=SUMPRODUCT(('BASE DE DADOS'!$J$4:$J$3000=B18)*('BASE DE DADOS'!$M$4:$M$3000="Cumprido"))} | E18: {=SUMPRODUCT(('BASE DE DADOS'!$J$4:$J$3000=B18)*('BASE DE DADOS'!$M$4:$M$3000="Não cumprido"))} | F18: =IF(C18=0,"-",TEXT(D18/C18,"0.0%"))
B19: Contrarrazões | C19: =COUNTIF('BASE DE DADOS'!$J$4:$J$3000,B19) | D19: {=SUMPRODUCT(('BASE DE DADOS'!$J$4:$J$3000=B19)*('BASE DE DADOS'!$M$4:$M$3000="Cumprido"))} | E19: {=SUMPRODUCT(('BASE DE DADOS'!$J$4:$J$3000=B19)*('BASE DE DADOS'!$M$4:$M$3000="Não cumprido"))} | F19: =IF(C19=0,"-",TEXT(D19/C19,"0.0%"))
B20: Audiência | C20: =COUNTIF('BASE DE DADOS'!$J$4:$J$3000,B20) | D20: {=SUMPRODUCT(('BASE DE DADOS'!$J$4:$J$3000=B20)*('BASE DE DADOS'!$M$4:$M$3000="Cumprido"))} | E20: {=SUMPRODUCT(('BASE DE DADOS'!$J$4:$J$3000=B20)*('BASE DE DADOS'!$M$4:$M$3000="Não cumprido"))} | F20: =IF(C20=0,"-",TEXT(D20/C20,"0.0%"))
B21: Embargos | C21: =COUNTIF('BASE DE DADOS'!$J$4:$J$3000,B21) | D21: {=SUMPRODUCT(('BASE DE DADOS'!$J$4:$J$3000=B21)*('BASE DE DADOS'!$M$4:$M$3000="Cumprido"))} | E21: {=SUMPRODUCT(('BASE DE DADOS'!$J$4:$J$3000=B21)*('BASE DE DADOS'!$M$4:$M$3000="Não cumprido"))} | F21: =IF(C21=0,"-",TEXT(D21/C21,"0.0%"))
B22: Evento | C22: =COUNTIF('BASE DE DADOS'!$J$4:$J$3000,B22) | D22: {=SUMPRODUCT(('BASE DE DADOS'!$J$4:$J$3000=B22)*('BASE DE DADOS'!$M$4:$M$3000="Cumprido"))} | E22: {=SUMPRODUCT(('BASE DE DADOS'!$J$4:$J$3000=B22)*('BASE DE DADOS'!$M$4:$M$3000="Não cumprido"))}
B23: Prazo | C23: =COUNTIF('BASE DE DADOS'!$J$4:$J$3000,B23) | D23: {=SUMPRODUCT(('BASE DE DADOS'!$J$4:$J$3000=B23)*('BASE DE DADOS'!$M$4:$M$3000="Cumprido"))} | E23: {=SUMPRODUCT(('BASE DE DADOS'!$J$4:$J$3000=B23)*('BASE DE DADOS'!$M$4:$M$3000="Não cumprido"))}
B24: Tarefa | C24: =COUNTIF('BASE DE DADOS'!$J$4:$J$3000,B24) | D24: {=SUMPRODUCT(('BASE DE DADOS'!$J$4:$J$3000=B24)*('BASE DE DADOS'!$M$4:$M$3000="Cumprido"))} | E24: {=SUMPRODUCT(('BASE DE DADOS'!$J$4:$J$3000=B24)*('BASE DE DADOS'!$M$4:$M$3000="Não cumprido"))}
B25: Outros | C25: =COUNTIF('BASE DE DADOS'!$J$4:$J$3000,B25) | D25: {=SUMPRODUCT(('BASE DE DADOS'!$J$4:$J$3000=B25)*('BASE DE DADOS'!$M$4:$M$3000="Cumprido"))} | E25: {=SUMPRODUCT(('BASE DE DADOS'!$J$4:$J$3000=B25)*('BASE DE DADOS'!$M$4:$M$3000="Não cumprido"))} | F25: =IF(C25=0,"-",TEXT(D25/C25,"0.0%"))
B27: PERFORMANCE POR ADVOGADO - PRAZOS
B28: Responsável | C28: Total Prazos | D28: Cumpridos | E28: Não Cumpridos | F28: Taxa (%)
B29: Ronaldo Koyama | C29: =IF(B29="","",COUNTIF('BASE DE DADOS'!$L$4:$L$3000,B29)) | D29: {=IF(B29="","",SUMPRODUCT(('BASE DE DADOS'!$L$4:$L$3000=B29)*('BASE DE DADOS'!$M$4:$M$3000="Cumprido")))} | E29: {=IF(B29="","",SUMPRODUCT(('BASE DE DADOS'!$L$4:$L$3000=B29)*('BASE DE DADOS'!$M$4:$M$3000="Não cumprido")))} | F29: =IF(OR(B29="",C29=0),"-",TEXT(D29/C29,"0.0%"))
B30: Lucas | C30: =IF(B30="","",COUNTIF('BASE DE DADOS'!$L$4:$L$3000,B30)) | D30: {=IF(B30="","",SUMPRODUCT(('BASE DE DADOS'!$L$4:$L$3000=B30)*('BASE DE DADOS'!$M$4:$M$3000="Cumprido")))} | E30: {=IF(B30="","",SUMPRODUCT(('BASE DE DADOS'!$L$4:$L$3000=B30)*('BASE DE DADOS'!$M$4:$M$3000="Não cumprido")))} | F30: =IF(OR(B30="",C30=0),"-",TEXT(D30/C30,"0.0%"))
B31: Luci | C31: =IF(B31="","",COUNTIF('BASE DE DADOS'!$L$4:$L$3000,B31)) | D31: {=IF(B31="","",SUMPRODUCT(('BASE DE DADOS'!$L$4:$L$3000=B31)*('BASE DE DADOS'!$M$4:$M$3000="Cumprido")))} | E31: {=IF(B31="","",SUMPRODUCT(('BASE DE DADOS'!$L$4:$L$3000=B31)*('BASE DE DADOS'!$M$4:$M$3000="Não cumprido")))} | F31: =IF(OR(B31="",C31=0),"-",TEXT(D31/C31,"0.0%"))
B32: Julia | C32: =IF(B32="","",COUNTIF('BASE DE DADOS'!$L$4:$L$3000,B32)) | D32: {=IF(B32="","",SUMPRODUCT(('BASE DE DADOS'!$L$4:$L$3000=B32)*('BASE DE DADOS'!$M$4:$M$3000="Cumprido")))} | E32: {=IF(B32="","",SUMPRODUCT(('BASE DE DADOS'!$L$4:$L$3000=B32)*('BASE DE DADOS'!$M$4:$M$3000="Não cumprido")))} | F32: =IF(OR(B32="",C32=0),"-",TEXT(D32/C32,"0.0%"))
B33: Pedro Victor | C33: =IF(B33="","",COUNTIF('BASE DE DADOS'!$L$4:$L$3000,B33)) | D33: {=IF(B33="","",SUMPRODUCT(('BASE DE DADOS'!$L$4:$L$3000=B33)*('BASE DE DADOS'!$M$4:$M$3000="Cumprido")))} | E33: {=IF(B33="","",SUMPRODUCT(('BASE DE DADOS'!$L$4:$L$3000=B33)*('BASE DE DADOS'!$M$4:$M$3000="Não cumprido")))} | F33: =IF(OR(B33="",C33=0),"-",TEXT(D33/C33,"0.0%"))
B34: Alexia | C34: =IF(B34="","",COUNTIF('BASE DE DADOS'!$L$4:$L$3000,B34)) | D34: {=IF(B34="","",SUMPRODUCT(('BASE DE DADOS'!$L$4:$L$3000=B34)*('BASE DE DADOS'!$M$4:$M$3000="Cumprido")))} | E34: {=IF(B34="","",SUMPRODUCT(('BASE DE DADOS'!$L$4:$L$3000=B34)*('BASE DE DADOS'!$M$4:$M$3000="Não cumprido")))} | F34: =IF(OR(B34="",C34=0),"-",TEXT(D34/C34,"0.0%"))
B35: Jessica | C35: =IF(B35="","",COUNTIF('BASE DE DADOS'!$L$4:$L$3000,B35)) | D35: {=IF(B35="","",SUMPRODUCT(('BASE DE DADOS'!$L$4:$L$3000=B35)*('BASE DE DADOS'!$M$4:$M$3000="Cumprido")))} | E35: {=IF(B35="","",SUMPRODUCT(('BASE DE DADOS'!$L$4:$L$3000=B35)*('BASE DE DADOS'!$M$4:$M$3000="Não cumprido")))} | F35: =IF(OR(B35="",C35=0),"-",TEXT(D35/C35,"0.0%"))
B36: Marelize Controladoria | C36: =IF(B36="","",COUNTIF('BASE DE DADOS'!$L$4:$L$3000,B36)) | D36: {=IF(B36="","",SUMPRODUCT(('BASE DE DADOS'!$L$4:$L$3000=B36)*('BASE DE DADOS'!$M$4:$M$3000="Cumprido")))} | E36: {=IF(B36="","",SUMPRODUCT(('BASE DE DADOS'!$L$4:$L$3000=B36)*('BASE DE DADOS'!$M$4:$M$3000="Não cumprido")))} | F36: =IF(OR(B36="",C36=0),"-",TEXT(D36/C36,"0.0%"))
B37: Renata Francisco Becker | C37: =IF(B37="","",COUNTIF('BASE DE DADOS'!$L$4:$L$3000,B37)) | D37: {=IF(B37="","",SUMPRODUCT(('BASE DE DADOS'!$L$4:$L$3000=B37)*('BASE DE DADOS'!$M$4:$M$3000="Cumprido")))} | E37: {=IF(B37="","",SUMPRODUCT(('BASE DE DADOS'!$L$4:$L$3000=B37)*('BASE DE DADOS'!$M$4:$M$3000="Não cumprido")))} | F37: =IF(OR(B37="",C37=0),"-",TEXT(D37/C37,"0.0%"))
A42: K Controllers | kcontrollers.com.br | Controladoria Jurídica na prática.
